[2024-01-16 15:36:48,266] {taskinstance.py:1159} INFO - Dependencies all met for <TaskInstance: dag_transfer_gdrive_to_postgresql.check_file_if_exists manual__2024-01-16T15:31:45.714362+00:00 [queued]>
[2024-01-16 15:36:48,273] {taskinstance.py:1159} INFO - Dependencies all met for <TaskInstance: dag_transfer_gdrive_to_postgresql.check_file_if_exists manual__2024-01-16T15:31:45.714362+00:00 [queued]>
[2024-01-16 15:36:48,273] {taskinstance.py:1356} INFO - 
--------------------------------------------------------------------------------
[2024-01-16 15:36:48,274] {taskinstance.py:1357} INFO - Starting attempt 2 of 3
[2024-01-16 15:36:48,274] {taskinstance.py:1358} INFO - 
--------------------------------------------------------------------------------
[2024-01-16 15:36:48,283] {taskinstance.py:1377} INFO - Executing <Task(PythonOperator): check_file_if_exists> on 2024-01-16 15:31:45.714362+00:00
[2024-01-16 15:36:48,286] {standard_task_runner.py:52} INFO - Started process 811 to run task
[2024-01-16 15:36:48,289] {standard_task_runner.py:79} INFO - Running: ['***', 'tasks', 'run', 'dag_transfer_gdrive_to_postgresql', 'check_file_if_exists', 'manual__2024-01-16T15:31:45.714362+00:00', '--job-id', '22', '--raw', '--subdir', 'DAGS_FOLDER/dag_gdrive_to_postgres.py', '--cfg-path', '/tmp/tmpon4tgiox', '--error-file', '/tmp/tmp8ddpkv86']
[2024-01-16 15:36:48,291] {standard_task_runner.py:80} INFO - Job 22: Subtask check_file_if_exists
[2024-01-16 15:36:48,329] {task_command.py:369} INFO - Running <TaskInstance: dag_transfer_gdrive_to_postgresql.check_file_if_exists manual__2024-01-16T15:31:45.714362+00:00 [running]> on host 3c1ede9470c0
[2024-01-16 15:36:48,378] {taskinstance.py:1571} INFO - Exporting the following env vars:
AIRFLOW_CTX_DAG_OWNER=***
AIRFLOW_CTX_DAG_ID=dag_transfer_gdrive_to_postgresql
AIRFLOW_CTX_TASK_ID=check_file_if_exists
AIRFLOW_CTX_EXECUTION_DATE=2024-01-16T15:31:45.714362+00:00
AIRFLOW_CTX_TRY_NUMBER=2
AIRFLOW_CTX_DAG_RUN_ID=manual__2024-01-16T15:31:45.714362+00:00
[2024-01-16 15:36:48,379] {logging_mixin.py:115} INFO - masuk kesini woy
[2024-01-16 15:36:48,379] {logging_mixin.py:115} INFO - 1
[2024-01-16 15:36:48,397] {logging_mixin.py:115} INFO - 2
[2024-01-16 15:36:48,398] {logging_mixin.py:115} INFO - authenticate start
[2024-01-16 15:36:48,398] {logging_mixin.py:115} INFO - Something went wrong bufsize must be an integer
[2024-01-16 15:36:48,399] {logging_mixin.py:115} INFO - Something went wrong bufsize must be an integer
[2024-01-16 15:36:48,399] {logging_mixin.py:115} INFO - Something went wrong bufsize must be an integer
[2024-01-16 15:36:48,399] {logging_mixin.py:115} INFO - Something went wrong bufsize must be an integer
[2024-01-16 15:36:48,399] {logging_mixin.py:115} INFO - authenticate after install packages
[2024-01-16 15:36:48,406] {logging_mixin.py:115} INFO - {
  "token": "ya29.a0AfB_byDjo9uXOpTfa11pGhbkV5TwzBGT3-zp64kVJ4gJVAG5Jpl8YupOM3j9VH0ZniotfxrsR0j0D-UXaCxi0ACEYiZj2UFSQhS9jmCwTBC4D8kRk7MA4Q681jhhfJlu6Hjnl-NCTquCgHp5tvEaR6AwEfuz2WHW8XCwaCgYKAewSARMSFQHGX2Mi5a7pO9e3UHhALowUGfxjvA0171",
  "refresh_token": "1//0gDIGWCrQ0eTWCgYIARAAGBASNwF-L9Ir_6zv2B2FhkmGi6bX4QONzgttohg7jHDOI5KMJCxmOeDx7Xu9zpUB8zgKAsxVZX7eKnE",
  "token_uri": "https://oauth2.googleapis.com/token",
  "client_id": "362841129103-mi8kcnjk2uk2hv5in782u9j7o9b4lj8b.apps.googleusercontent.com",
  "client_secret": "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",
  "scopes": [
    "https://www.googleapis.com/auth/drive.metadata.readonly",
    "https://www.googleapis.com/auth/drive.file",
    "https://www.googleapis.com/auth/drive.readonly",
    "https://www.googleapis.com/auth/drive"
  ],
  "expiry": "2024-01-13T12:27:21.158492Z"
}
[2024-01-16 15:36:48,406] {logging_mixin.py:115} INFO - {'token': 'ya29.a0AfB_byDjo9uXOpTfa11pGhbkV5TwzBGT3-zp64kVJ4gJVAG5Jpl8YupOM3j9VH0ZniotfxrsR0j0D-UXaCxi0ACEYiZj2UFSQhS9jmCwTBC4D8kRk7MA4Q681jhhfJlu6Hjnl-NCTquCgHp5tvEaR6AwEfuz2WHW8XCwaCgYKAewSARMSFQHGX2Mi5a7pO9e3UHhALowUGfxjvA0171', 'refresh_token': '1//0gDIGWCrQ0eTWCgYIARAAGBASNwF-L9Ir_6zv2B2FhkmGi6bX4QONzgttohg7jHDOI5KMJCxmOeDx7Xu9zpUB8zgKAsxVZX7eKnE', 'token_uri': 'https://oauth2.googleapis.com/token', 'client_id': '362841129103-mi8kcnjk2uk2hv5in782u9j7o9b4lj8b.apps.googleusercontent.com', 'client_secret': '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', 'scopes': ['https://www.googleapis.com/auth/drive.metadata.readonly', 'https://www.googleapis.com/auth/drive.file', 'https://www.googleapis.com/auth/drive.readonly', 'https://www.googleapis.com/auth/drive'], 'expiry': '2024-01-13T12:27:21.158492Z'}
[2024-01-16 15:36:48,407] {logging_mixin.py:115} INFO - Credentials from token ya29.a0AfB_byDjo9uXOpTfa11pGhbkV5TwzBGT3-zp64kVJ4gJVAG5Jpl8YupOM3j9VH0ZniotfxrsR0j0D-UXaCxi0ACEYiZj2UFSQhS9jmCwTBC4D8kRk7MA4Q681jhhfJlu6Hjnl-NCTquCgHp5tvEaR6AwEfuz2WHW8XCwaCgYKAewSARMSFQHGX2Mi5a7pO9e3UHhALowUGfxjvA0171
[2024-01-16 15:36:48,407] {logging_mixin.py:115} INFO - <google.oauth2.credentials.Credentials object at 0xffff9451c0d0>
[2024-01-16 15:36:49,837] {google_auth_httplib2.py:242} INFO - Refreshing credentials due to a 401 response. Attempt 1/2.
[2024-01-16 15:36:50,638] {logging_mixin.py:115} INFO - The 'dataset' files does not exist in 'Shared with me' in folder 'dataset'.
[2024-01-16 15:36:50,639] {python.py:173} INFO - Done. Returned value was: end
[2024-01-16 15:36:50,671] {taskinstance.py:1400} INFO - Marking task as SUCCESS. dag_id=dag_transfer_gdrive_to_postgresql, task_id=check_file_if_exists, execution_date=20240116T153145, start_date=20240116T153648, end_date=20240116T153650
[2024-01-16 15:36:50,717] {local_task_job.py:156} INFO - Task exited with return code 0
[2024-01-16 15:36:50,749] {local_task_job.py:273} INFO - 1 downstream tasks scheduled from follow-on schedule check
