[2024-01-16 16:33:03,766] {taskinstance.py:1159} INFO - Dependencies all met for <TaskInstance: dag_transfer_gdrive_to_postgresql.upsert_data manual__2024-01-16T16:29:16.093065+00:00 [queued]>
[2024-01-16 16:33:03,772] {taskinstance.py:1159} INFO - Dependencies all met for <TaskInstance: dag_transfer_gdrive_to_postgresql.upsert_data manual__2024-01-16T16:29:16.093065+00:00 [queued]>
[2024-01-16 16:33:03,773] {taskinstance.py:1356} INFO - 
--------------------------------------------------------------------------------
[2024-01-16 16:33:03,773] {taskinstance.py:1357} INFO - Starting attempt 1 of 3
[2024-01-16 16:33:03,773] {taskinstance.py:1358} INFO - 
--------------------------------------------------------------------------------
[2024-01-16 16:33:03,781] {taskinstance.py:1377} INFO - Executing <Task(PythonOperator): upsert_data> on 2024-01-16 16:29:16.093065+00:00
[2024-01-16 16:33:03,785] {standard_task_runner.py:52} INFO - Started process 2400 to run task
[2024-01-16 16:33:03,788] {standard_task_runner.py:79} INFO - Running: ['***', 'tasks', 'run', 'dag_transfer_gdrive_to_postgresql', 'upsert_data', 'manual__2024-01-16T16:29:16.093065+00:00', '--job-id', '69', '--raw', '--subdir', 'DAGS_FOLDER/dag_gdrive_to_postgres.py', '--cfg-path', '/tmp/tmp430h9zvo', '--error-file', '/tmp/tmp9dxw5226']
[2024-01-16 16:33:03,789] {standard_task_runner.py:80} INFO - Job 69: Subtask upsert_data
[2024-01-16 16:33:03,824] {task_command.py:369} INFO - Running <TaskInstance: dag_transfer_gdrive_to_postgresql.upsert_data manual__2024-01-16T16:29:16.093065+00:00 [running]> on host 3c1ede9470c0
[2024-01-16 16:33:03,871] {taskinstance.py:1571} INFO - Exporting the following env vars:
AIRFLOW_CTX_DAG_OWNER=***
AIRFLOW_CTX_DAG_ID=dag_transfer_gdrive_to_postgresql
AIRFLOW_CTX_TASK_ID=upsert_data
AIRFLOW_CTX_EXECUTION_DATE=2024-01-16T16:29:16.093065+00:00
AIRFLOW_CTX_TRY_NUMBER=1
AIRFLOW_CTX_DAG_RUN_ID=manual__2024-01-16T16:29:16.093065+00:00
[2024-01-16 16:33:04,173] {taskinstance.py:1889} ERROR - Task failed with exception
Traceback (most recent call last):
  File "/home/airflow/.local/lib/python3.7/site-packages/airflow/operators/python.py", line 171, in execute
    return_value = self.execute_callable()
  File "/home/airflow/.local/lib/python3.7/site-packages/airflow/operators/python.py", line 189, in execute_callable
    return self.python_callable(*self.op_args, **self.op_kwargs)
  File "/opt/airflow/dags/dag_gdrive_to_postgres.py", line 223, in _upsert_data
    engine = create_engine(f'postgresql://{db_params["user"]}: {db_params["password"]}@{db_params["host"]}: {db_params["port"]}/{db_params["dbname"]}')
KeyError: 'dbname'
[2024-01-16 16:33:04,180] {taskinstance.py:1400} INFO - Marking task as UP_FOR_RETRY. dag_id=dag_transfer_gdrive_to_postgresql, task_id=upsert_data, execution_date=20240116T162916, start_date=20240116T163303, end_date=20240116T163304
[2024-01-16 16:33:04,186] {standard_task_runner.py:97} ERROR - Failed to execute job 69 for task upsert_data ('dbname'; 2400)
[2024-01-16 16:33:04,212] {local_task_job.py:156} INFO - Task exited with return code 1
[2024-01-16 16:33:04,240] {local_task_job.py:273} INFO - 0 downstream tasks scheduled from follow-on schedule check
