[2024-01-16 16:34:53,428] {taskinstance.py:1159} INFO - Dependencies all met for <TaskInstance: dag_transfer_gdrive_to_postgresql.upsert_data manual__2024-01-16T16:29:16.093065+00:00 [queued]>
[2024-01-16 16:34:53,434] {taskinstance.py:1159} INFO - Dependencies all met for <TaskInstance: dag_transfer_gdrive_to_postgresql.upsert_data manual__2024-01-16T16:29:16.093065+00:00 [queued]>
[2024-01-16 16:34:53,435] {taskinstance.py:1356} INFO - 
--------------------------------------------------------------------------------
[2024-01-16 16:34:53,435] {taskinstance.py:1357} INFO - Starting attempt 2 of 4
[2024-01-16 16:34:53,435] {taskinstance.py:1358} INFO - 
--------------------------------------------------------------------------------
[2024-01-16 16:34:53,444] {taskinstance.py:1377} INFO - Executing <Task(PythonOperator): upsert_data> on 2024-01-16 16:29:16.093065+00:00
[2024-01-16 16:34:53,448] {standard_task_runner.py:52} INFO - Started process 2468 to run task
[2024-01-16 16:34:53,451] {standard_task_runner.py:79} INFO - Running: ['***', 'tasks', 'run', 'dag_transfer_gdrive_to_postgresql', 'upsert_data', 'manual__2024-01-16T16:29:16.093065+00:00', '--job-id', '70', '--raw', '--subdir', 'DAGS_FOLDER/dag_gdrive_to_postgres.py', '--cfg-path', '/tmp/tmpwqssed8x', '--error-file', '/tmp/tmp546g2w6g']
[2024-01-16 16:34:53,452] {standard_task_runner.py:80} INFO - Job 70: Subtask upsert_data
[2024-01-16 16:34:53,493] {task_command.py:369} INFO - Running <TaskInstance: dag_transfer_gdrive_to_postgresql.upsert_data manual__2024-01-16T16:29:16.093065+00:00 [running]> on host 3c1ede9470c0
[2024-01-16 16:34:53,548] {taskinstance.py:1571} INFO - Exporting the following env vars:
AIRFLOW_CTX_DAG_OWNER=***
AIRFLOW_CTX_DAG_ID=dag_transfer_gdrive_to_postgresql
AIRFLOW_CTX_TASK_ID=upsert_data
AIRFLOW_CTX_EXECUTION_DATE=2024-01-16T16:29:16.093065+00:00
AIRFLOW_CTX_TRY_NUMBER=2
AIRFLOW_CTX_DAG_RUN_ID=manual__2024-01-16T16:29:16.093065+00:00
[2024-01-16 16:34:53,868] {taskinstance.py:1889} ERROR - Task failed with exception
Traceback (most recent call last):
  File "/home/airflow/.local/lib/python3.7/site-packages/airflow/operators/python.py", line 171, in execute
    return_value = self.execute_callable()
  File "/home/airflow/.local/lib/python3.7/site-packages/airflow/operators/python.py", line 189, in execute_callable
    return self.python_callable(*self.op_args, **self.op_kwargs)
  File "/opt/airflow/dags/dag_gdrive_to_postgres.py", line 223, in _upsert_data
    engine = create_engine(f'postgresql://{db_params["user"]}: {db_params["password"]}@{db_params["host"]}: {db_params["port"]}/{db_params["dbname"]}')
KeyError: 'dbname'
[2024-01-16 16:34:53,875] {taskinstance.py:1400} INFO - Marking task as UP_FOR_RETRY. dag_id=dag_transfer_gdrive_to_postgresql, task_id=upsert_data, execution_date=20240116T162916, start_date=20240116T163453, end_date=20240116T163453
[2024-01-16 16:34:53,881] {standard_task_runner.py:97} ERROR - Failed to execute job 70 for task upsert_data ('dbname'; 2468)
[2024-01-16 16:34:53,922] {local_task_job.py:156} INFO - Task exited with return code 1
[2024-01-16 16:34:53,950] {local_task_job.py:273} INFO - 0 downstream tasks scheduled from follow-on schedule check
