[2024-01-16 15:55:39,355] {taskinstance.py:1159} INFO - Dependencies all met for <TaskInstance: dag_transfer_gdrive_to_postgresql.process_csv manual__2024-01-16T15:45:20.290985+00:00 [queued]>
[2024-01-16 15:55:39,362] {taskinstance.py:1159} INFO - Dependencies all met for <TaskInstance: dag_transfer_gdrive_to_postgresql.process_csv manual__2024-01-16T15:45:20.290985+00:00 [queued]>
[2024-01-16 15:55:39,363] {taskinstance.py:1356} INFO - 
--------------------------------------------------------------------------------
[2024-01-16 15:55:39,363] {taskinstance.py:1357} INFO - Starting attempt 3 of 3
[2024-01-16 15:55:39,363] {taskinstance.py:1358} INFO - 
--------------------------------------------------------------------------------
[2024-01-16 15:55:39,375] {taskinstance.py:1377} INFO - Executing <Task(PythonOperator): process_csv> on 2024-01-16 15:45:20.290985+00:00
[2024-01-16 15:55:39,378] {standard_task_runner.py:52} INFO - Started process 1357 to run task
[2024-01-16 15:55:39,382] {standard_task_runner.py:79} INFO - Running: ['***', 'tasks', 'run', 'dag_transfer_gdrive_to_postgresql', 'process_csv', 'manual__2024-01-16T15:45:20.290985+00:00', '--job-id', '40', '--raw', '--subdir', 'DAGS_FOLDER/dag_gdrive_to_postgres.py', '--cfg-path', '/tmp/tmpofkv4n_h', '--error-file', '/tmp/tmpz9gsc9zk']
[2024-01-16 15:55:39,383] {standard_task_runner.py:80} INFO - Job 40: Subtask process_csv
[2024-01-16 15:55:39,426] {task_command.py:369} INFO - Running <TaskInstance: dag_transfer_gdrive_to_postgresql.process_csv manual__2024-01-16T15:45:20.290985+00:00 [running]> on host 3c1ede9470c0
[2024-01-16 15:55:39,519] {taskinstance.py:1571} INFO - Exporting the following env vars:
AIRFLOW_CTX_DAG_OWNER=***
AIRFLOW_CTX_DAG_ID=dag_transfer_gdrive_to_postgresql
AIRFLOW_CTX_TASK_ID=process_csv
AIRFLOW_CTX_EXECUTION_DATE=2024-01-16T15:45:20.290985+00:00
AIRFLOW_CTX_TRY_NUMBER=3
AIRFLOW_CTX_DAG_RUN_ID=manual__2024-01-16T15:45:20.290985+00:00
[2024-01-16 15:55:39,530] {taskinstance.py:1889} ERROR - Task failed with exception
Traceback (most recent call last):
  File "/home/airflow/.local/lib/python3.7/site-packages/airflow/operators/python.py", line 171, in execute
    return_value = self.execute_callable()
  File "/home/airflow/.local/lib/python3.7/site-packages/airflow/operators/python.py", line 189, in execute_callable
    return self.python_callable(*self.op_args, **self.op_kwargs)
  File "/opt/airflow/dags/dag_gdrive_to_postgres.py", line 136, in _process_csv
    for file in dataset_files:
TypeError: 'NoneType' object is not iterable
[2024-01-16 15:55:39,541] {taskinstance.py:1400} INFO - Marking task as FAILED. dag_id=dag_transfer_gdrive_to_postgresql, task_id=process_csv, execution_date=20240116T154520, start_date=20240116T155539, end_date=20240116T155539
[2024-01-16 15:55:39,549] {standard_task_runner.py:97} ERROR - Failed to execute job 40 for task process_csv ('NoneType' object is not iterable; 1357)
[2024-01-16 15:55:39,555] {local_task_job.py:156} INFO - Task exited with return code 1
[2024-01-16 15:55:39,586] {local_task_job.py:273} INFO - 0 downstream tasks scheduled from follow-on schedule check
